<?xml version="1.0"?>
<robot name="peon_movil">

  <link name="base_link">
    <visual>
      <origin xyz="0 0 0" rpy="0 0 0"/>
      <geometry><mesh filename="package://peon_movil_description/urdf/meshes_stl/base.stl" scale="0.001 0.001 0.001"/></geometry>
      <material name="base_link_mat"><color rgba="0.3 0.3 0.35 1"/></material>
    </visual>
    <collision>
      <origin xyz="0 0 0.0" rpy="0 0 0"/>
      <geometry><box size="0.241 0.2 0.1"/></geometry>
    </collision>
    <inertial>
      <origin xyz="0.00000 0.00000 0.00000" rpy="0 0 0"/>
      <mass value="1.4000"/>
      <inertia ixx="5.833333e-03" ixy="0" ixz="0" iyy="7.942783e-03" iyz="0" izz="1.144278e-02"/>
    </inertial>
  </link>

  <link name="wheel_fl">
    <visual>
      <origin xyz="0 0 0" rpy="0 0 0"/>
      <geometry><mesh filename="package://peon_movil_description/urdf/meshes_stl/wheel_fl.stl" scale="0.001 0.001 0.001"/></geometry>
      <material name="wheel_mat"><color rgba="0.1 0.1 0.1 1"/></material>
    </visual>
    <collision>
      <origin xyz="0 0 0" rpy="1.5708 0 0"/>
      <geometry><cylinder radius="0.041" length="0.0425"/></geometry>
    </collision>
    <inertial>
      <origin xyz="0.00000 0.00000 0.00000" rpy="0 0 0"/>
      <mass value="0.0850"/>
      <inertia ixx="4.851552e-05" ixy="0" ixz="0" iyy="7.144250e-05" iyz="0" izz="4.851552e-05"/>
    </inertial>
  </link>
  <joint name="wheel_fl_joint" type="continuous">
    <parent link="base_link"/>
    <child link="wheel_fl"/>
    <origin xyz="0.0855 0.0873 -0.0412" rpy="0 0 0"/>
    <axis xyz="0 1 0"/>
  </joint>

  <link name="wheel_fr">
    <visual>
      <origin xyz="0 0 0" rpy="0 0 0"/>
      <geometry><mesh filename="package://peon_movil_description/urdf/meshes_stl/wheel_fr.stl" scale="0.001 0.001 0.001"/></geometry>
      <material name="wheel_mat"><color rgba="0.1 0.1 0.1 1"/></material>
    </visual>
    <collision>
      <origin xyz="0 0 0" rpy="1.5708 0 0"/>
      <geometry><cylinder radius="0.041" length="0.0425"/></geometry>
    </collision>
    <inertial>
      <origin xyz="0.00000 0.00000 0.00000" rpy="0 0 0"/>
      <mass value="0.0850"/>
      <inertia ixx="4.851552e-05" ixy="0" ixz="0" iyy="7.144250e-05" iyz="0" izz="4.851552e-05"/>
    </inertial>
  </link>
  <joint name="wheel_fr_joint" type="continuous">
    <parent link="base_link"/>
    <child link="wheel_fr"/>
    <origin xyz="0.0855 -0.0873 -0.0412" rpy="0 0 0"/>
    <axis xyz="0 1 0"/>
  </joint>

  <link name="wheel_ml">
    <visual>
      <origin xyz="0 0 0" rpy="0 0 0"/>
      <geometry><mesh filename="package://peon_movil_description/urdf/meshes_stl/wheel_ml.stl" scale="0.001 0.001 0.001"/></geometry>
      <material name="wheel_mat"><color rgba="0.1 0.1 0.1 1"/></material>
    </visual>
    <collision>
      <origin xyz="0 0 0" rpy="1.5708 0 0"/>
      <geometry><cylinder radius="0.041" length="0.0425"/></geometry>
    </collision>
    <inertial>
      <origin xyz="0.00000 0.00000 0.00000" rpy="0 0 0"/>
      <mass value="0.0850"/>
      <inertia ixx="4.851552e-05" ixy="0" ixz="0" iyy="7.144250e-05" iyz="0" izz="4.851552e-05"/>
    </inertial>
  </link>
  <joint name="wheel_ml_joint" type="continuous">
    <parent link="base_link"/>
    <child link="wheel_ml"/>
    <origin xyz="0.0 0.0883 -0.0412" rpy="0 0 0"/>
    <axis xyz="0 1 0"/>
  </joint>

  <link name="wheel_mr">
    <visual>
      <origin xyz="0 0 0" rpy="0 0 0"/>
      <geometry><mesh filename="package://peon_movil_description/urdf/meshes_stl/wheel_mr.stl" scale="0.001 0.001 0.001"/></geometry>
      <material name="wheel_mat"><color rgba="0.1 0.1 0.1 1"/></material>
    </visual>
    <collision>
      <origin xyz="0 0 0" rpy="1.5708 0 0"/>
      <geometry><cylinder radius="0.041" length="0.0425"/></geometry>
    </collision>
    <inertial>
      <origin xyz="0.00000 0.00000 0.00000" rpy="0 0 0"/>
      <mass value="0.0850"/>
      <inertia ixx="4.851552e-05" ixy="0" ixz="0" iyy="7.144250e-05" iyz="0" izz="4.851552e-05"/>
    </inertial>
  </link>
  <joint name="wheel_mr_joint" type="continuous">
    <parent link="base_link"/>
    <child link="wheel_mr"/>
    <origin xyz="0.0 -0.0883 -0.0412" rpy="0 0 0"/>
    <axis xyz="0 1 0"/>
  </joint>

  <link name="wheel_rl">
    <visual>
      <origin xyz="0 0 0" rpy="0 0 0"/>
      <geometry><mesh filename="package://peon_movil_description/urdf/meshes_stl/wheel_rl.stl" scale="0.001 0.001 0.001"/></geometry>
      <material name="wheel_mat"><color rgba="0.1 0.1 0.1 1"/></material>
    </visual>
    <collision>
      <origin xyz="0 0 0" rpy="1.5708 0 0"/>
      <geometry><cylinder radius="0.041" length="0.0425"/></geometry>
    </collision>
    <inertial>
      <origin xyz="0.00000 0.00000 0.00000" rpy="0 0 0"/>
      <mass value="0.0850"/>
      <inertia ixx="4.851552e-05" ixy="0" ixz="0" iyy="7.144250e-05" iyz="0" izz="4.851552e-05"/>
    </inertial>
  </link>
  <joint name="wheel_rl_joint" type="continuous">
    <parent link="base_link"/>
    <child link="wheel_rl"/>
    <origin xyz="-0.0855 0.0873 -0.0412" rpy="0 0 0"/>
    <axis xyz="0 1 0"/>
  </joint>

  <link name="wheel_rr">
    <visual>
      <origin xyz="0 0 0" rpy="0 0 0"/>
      <geometry><mesh filename="package://peon_movil_description/urdf/meshes_stl/wheel_rr.stl" scale="0.001 0.001 0.001"/></geometry>
      <material name="wheel_mat"><color rgba="0.1 0.1 0.1 1"/></material>
    </visual>
    <collision>
      <origin xyz="0 0 0" rpy="1.5708 0 0"/>
      <geometry><cylinder radius="0.041" length="0.0425"/></geometry>
    </collision>
    <inertial>
      <origin xyz="0.00000 0.00000 0.00000" rpy="0 0 0"/>
      <mass value="0.0850"/>
      <inertia ixx="4.851552e-05" ixy="0" ixz="0" iyy="7.144250e-05" iyz="0" izz="4.851552e-05"/>
    </inertial>
  </link>
  <joint name="wheel_rr_joint" type="continuous">
    <parent link="base_link"/>
    <child link="wheel_rr"/>
    <origin xyz="-0.0855 -0.0873 -0.0412" rpy="0 0 0"/>
    <axis xyz="0 1 0"/>
  </joint>

  <link name="pan_link">
    <visual>
      <origin xyz="0 0 0" rpy="0 0 0"/>
      <geometry><mesh filename="package://peon_movil_description/urdf/meshes_stl/pan.stl" scale="0.001 0.001 0.001"/></geometry>
      <material name="pan_link_mat"><color rgba="0.5 0.5 0.5 1"/></material>
    </visual>
    <collision>
      <origin xyz="0 0 0.0" rpy="0 0 0"/>
      <geometry><box size="0.064 0.042 0.053"/></geometry>
    </collision>
    <inertial>
      <origin xyz="0.00000 0.00000 0.00000" rpy="0 0 0"/>
      <mass value="0.0800"/>
      <inertia ixx="3.048667e-05" ixy="0" ixz="0" iyy="4.603333e-05" iyz="0" izz="3.906667e-05"/>
    </inertial>
  </link>
  <joint name="pan_joint" type="revolute">
    <parent link="base_link"/>
    <child link="pan_link"/>
    <origin xyz="0.0087 0.0 0.0475" rpy="0 0 0"/>
    <axis xyz="0 0 1"/>
    <limit lower="-3.14159" upper="3.14159" effort="5" velocity="3"/>
  </joint>

  <link name="tilt_link">
    <visual>
      <origin xyz="0 0 0" rpy="0 0 0"/>
      <geometry><mesh filename="package://peon_movil_description/urdf/meshes_stl/tilt.stl" scale="0.001 0.001 0.001"/></geometry>
      <material name="tilt_link_mat"><color rgba="0.5 0.5 0.5 1"/></material>
    </visual>
    <collision>
      <origin xyz="0 0 0.0" rpy="0 0 0"/>
      <geometry><box size="0.075 0.046 0.055"/></geometry>
    </collision>
    <inertial>
      <origin xyz="0.00000 0.00000 0.00000" rpy="0 0 0"/>
      <mass value="0.0600"/>
      <inertia ixx="2.570500e-05" ixy="0" ixz="0" iyy="4.325000e-05" iyz="0" izz="3.870500e-05"/>
    </inertial>
  </link>
  <joint name="tilt_joint" type="revolute">
    <parent link="pan_link"/>
    <child link="tilt_link"/>
    <origin xyz="-0.0124 0.0 0.0835" rpy="0 0 0"/>
    <axis xyz="0 1 0"/>
    <limit lower="-1.5708" upper="1.5708" effort="5" velocity="3"/>
  </joint>

  <link name="camera_link">
    <visual>
      <origin xyz="0 0 0" rpy="0 0 0"/>
      <geometry><mesh filename="package://peon_movil_description/urdf/meshes_stl/camera.stl" scale="0.001 0.001 0.001"/></geometry>
      <material name="camera_link_mat"><color rgba="0.05 0.05 0.05 1"/></material>
    </visual>
    <collision>
      <origin xyz="0 0 0.0" rpy="0 0 0"/>
      <geometry><box size="0.08 0.046 0.055"/></geometry>
    </collision>
    <inertial>
      <origin xyz="0.00000 0.00000 0.00000" rpy="0 0 0"/>
      <mass value="0.0300"/>
      <inertia ixx="1.285250e-05" ixy="0" ixz="0" iyy="2.356250e-05" iyz="0" izz="2.129000e-05"/>
    </inertial>
  </link>
  <joint name="camera_joint" type="fixed">
    <parent link="tilt_link"/>
    <child link="camera_link"/>
    <origin xyz="-0.0263 0.0 0.021" rpy="0 0 0"/>
  </joint>

  <link name="camera_optical_frame"/>
  <joint name="camera_optical_joint" type="fixed">
    <parent link="camera_link"/>
    <child link="camera_optical_frame"/>
    <origin xyz="0 0 0" rpy="-1.5708 0 -1.5708"/>
  </joint>

</robot>
